<?xml version="1.0"?>
<robot name="blimp">
  <link name="base">
    <visual>
      <origin rpy="0 1.57075 0" xyz="0 0 0"/>
      <geometry>
        <mesh filename="../meshes/blimp_body/blimp_body_v4.dae" scale="1 1 1"/>
      </geometry>
    </visual>
    <collision>
      <origin rpy="0 1.57075 0" xyz="0.2 0 0"/>
      <geometry>
        <cylinder length="3.5" radius="0.9"/>
      </geometry>
    </collision>
    <inertial>
      <mass value="4.622"/>
      <inertia ixx="1.8719" ixy="0.0" ixz="0.0" iyy="5.6542" iyz="0.0" izz="5.6542"/>
    </inertial>
  </link>

  <link name="gondola">
    <visual>
      <origin rpy="0 -0.0872665 0" xyz="1.15 0 -1.05"/>
      <geometry>
        <mesh filename="../meshes/blimp_gondola/blimp_gondola_v4.dae" scale="1 1 1"/>
      </geometry>
    </visual>
    <collision>
      <origin rpy="0 -0.0872665 0" xyz="1.15 0 -1.05"/>
      <geometry>
        <box size="0.32 0.16 0.2"/>
      </geometry>
    </collision>
    <inertial>
      <mass value="2.605"/>
      <inertia ixx="0.006" ixy="0.0" ixz="0.0" iyy="0.0199" iyz="0.0" izz="0.0186"/>
    </inertial>
  </link>

  <link name="blimp_support1">
    <visual>
      <origin rpy="0.174533 0 0" xyz="1.15 0.17 -1.25"/>
      <geometry>
        <mesh filename="../meshes/blimp_support/blimp_support_v5.dae" scale="1.0 1.0 1.0"/>
      </geometry>
    </visual>
    <!-- <inertial>
      <mass value="0.0"/>
      <inertia ixx="0.0" ixy="0.0" ixz="0.0" iyy="0.0" iyz="0.0" izz="0.0"/>
    </inertial> -->
  </link>

  <link name="blimp_support2">
    <visual>
      <origin rpy="0.174533 0 3.14159" xyz="1.15 -0.17 -1.25"/>
      <geometry>
        <mesh filename="../meshes/blimp_support/blimp_support_v5.dae" scale="1.0 1.0 1.0"/>
      </geometry>
    </visual>
    <!-- <inertial>
      <mass value="0.0"/>
      <inertia ixx="0.0" ixy="0.0" ixz="0.0" iyy="0.0" iyz="0.0" izz="0.0"/>
    </inertial> -->
  </link>

  <link name="blimp_stick">
    <visual>
      <origin rpy="0 0 0" xyz="0 0 0"/>
      <geometry>
        <mesh filename="../meshes/blimp_wing/blimp_stick_v2.dae" scale="1.05 1.05 0.5"/>
      </geometry>
    </visual>
    <inertial>
      <mass value="0.2"/>
      <inertia ixx="0.0002" ixy="0.0" ixz="0.0" iyy="0.0002" iyz="0.0" izz="0.0002"/>
    </inertial>
  </link>

  <link name="blimp_wing1">
    <visual>
      <geometry>
        <mesh filename="../meshes/blimp_wing/blimp_wing_v2.dae" scale="0.9 0.9 0.9"/>
      </geometry>
    </visual>
    <inertial>
      <mass value="0.0"/>
      <inertia ixx="0.0" ixy="0.0" ixz="0.0" iyy="0.0" iyz="0.0" izz="0.0"/>
    </inertial>
  </link>

  <link name="blimp_wing2">
    <visual>
      <geometry>
        <mesh filename="../meshes/blimp_wing/blimp_wing_v2.dae" scale="0.9 0.9 0.9"/>
      </geometry>
    </visual>
    <inertial>
      <mass value="0.0"/>
      <inertia ixx="0.0" ixy="0.0" ixz="0.0" iyy="0.0" iyz="0.0" izz="0.0"/>
    </inertial>
  </link>

  <link name="blimp_rud_right">
    <visual>
      <geometry>
        <mesh filename="../meshes/blimp_fin/blimp_top_rud_part1_v3.dae" scale="1 1 1"/>
      </geometry>
    </visual>
    <collision>
      <geometry>
        <box size="0.5 0.03 0.5"/>
      </geometry>
    </collision>
    <inertial>
      <mass value="0.3"/>
      <inertia ixx="0.001" ixy="0.0" ixz="0.0" iyy="0.001" iyz="0.0" izz="0.001"/>
    </inertial>
  </link>

  <link name="rud_right">
    <visual>
      <origin xyz="-0.14 0 0"/>
      <geometry>
        <mesh filename="../meshes/blimp_fin/blimp_top_rud_part2_v5.dae" scale="1 1 1"/>
      </geometry>
    </visual>
    <collision>
      <origin xyz="-0.14 0 0"/>
      <geometry>
        <box size="0.22 0.03 0.5"/>
      </geometry>
    </collision>
    <inertial>
      <mass value="0.07"/>
      <inertia ixx="0.001" ixy="0.0" ixz="0.0" iyy="0.001" iyz="0.0" izz="0.001"/>
    </inertial>
  </link>

  <link name="blimp_rud_left">
    <visual>
      <geometry>
        <mesh filename="../meshes/blimp_fin/blimp_top_rud_part1_v3.dae" scale="1 1 1"/>
      </geometry>
    </visual>
    <collision>
      <geometry>
        <box size="0.5 0.03 0.5"/>
      </geometry>
    </collision>
    <inertial>
      <mass value="0.3"/>
      <inertia ixx="0.001" ixy="0.0" ixz="0.0" iyy="0.001" iyz="0.0" izz="0.001"/>
    </inertial>
  </link>

  <link name="rud_left">
    <visual>
      <origin xyz="-0.14 0 0"/>
      <geometry>
        <mesh filename="../meshes/blimp_fin/blimp_top_rud_part2_v5.dae" scale="1 1 1"/>
      </geometry>
    </visual>
    <collision>
      <origin xyz="-0.14 0 0"/>
      <geometry>
        <box size="0.22 0.03 0.5"/>
      </geometry>
    </collision>
    <inertial>
      <mass value="0.07"/>
      <inertia ixx="0.001" ixy="0.0" ixz="0.0" iyy="0.001" iyz="0.0" izz="0.001"/>
    </inertial>
  </link>

  <link name="blimp_rud_top">
    <visual>
      <geometry>
        <mesh filename="../meshes/blimp_fin/blimp_top_rud_part1_v3.dae" scale="1 1 1"/>
      </geometry>
    </visual>
    <collision>
      <geometry>
        <box size="0.5 0.03 0.5"/>
      </geometry>
    </collision>
    <inertial>
      <mass value="0.3"/>
      <inertia ixx="0.001" ixy="0.0" ixz="0.0" iyy="0.001" iyz="0.0" izz="0.001"/>
    </inertial>
  </link>

  <link name="rud_top">
    <visual>
      <origin xyz="-0.14 0 0"/>
      <geometry>
        <mesh filename="../meshes/blimp_fin/blimp_top_rud_part2_v5.dae" scale="1 1 1"/>
      </geometry>
    </visual>
    <collision>
      <origin xyz="-0.14 0 0"/>
      <geometry>
        <box size="0.22 0.03 0.5"/>
      </geometry>
    </collision>
    <inertial>
      <mass value="0.07"/>
      <inertia ixx="0.001" ixy="0.0" ixz="0.0" iyy="0.001" iyz="0.0" izz="0.001"/>
    </inertial>
  </link>


  <link name="blimp_rud_bot">
    <visual>
      <geometry>
        <mesh filename="../meshes/blimp_fin/blimp_bot_rud_part1_v3.dae" scale="1 1 1"/>
      </geometry>
    </visual>
    <collision>
      <geometry>
        <box size="0.5 0.03 0.5"/>
      </geometry>
    </collision>
    <inertial>
      <mass value="0.3"/>
      <inertia ixx="0.001" ixy="0.0" ixz="0.0" iyy="0.001" iyz="0.0" izz="0.001"/>
    </inertial>
  </link>

  <link name="rud_bot">
    <visual>
      <origin xyz="-0.14 0 0"/>
      <geometry>
        <mesh filename="../meshes/blimp_fin/blimp_top_rud_part2_v5.dae" scale="1 1 1"/>
      </geometry>
    </visual>
    <collision>
      <origin xyz="-0.14 0 0"/>
      <geometry>
        <box size="0.22 0.03 0.5"/>
      </geometry>
    </collision>
    <inertial>
      <mass value="0.07"/>
      <inertia ixx="0.001" ixy="0.0" ixz="0.0" iyy="0.001" iyz="0.0" izz="0.001"/>
    </inertial>
  </link>

  <joint name="base_gondola" type="fixed">
    <origin xyz="0 0 0"/>
    <parent link="base"/>
    <child link="gondola"/>
  </joint>

  <joint name="gondola_support1" type="fixed">
    <origin xyz="0 0 0"/>
    <parent link="gondola"/>
    <child link="blimp_support1"/>
  </joint>

  <joint name="gondola_support2" type="fixed">
    <origin xyz="0 0 0"/>
    <parent link="gondola"/>
    <child link="blimp_support2"/>
  </joint>

  <joint name="stick_wing1" type="fixed">
    <origin rpy="-1.57075 0 0" xyz="0 0 0.37"/>
    <parent link="blimp_stick"/>
    <child link="blimp_wing1"/>
  </joint>

  <joint name="stick_wing2" type="fixed">
    <origin rpy="-1.57075 0 0" xyz="0 0 -0.37"/>
    <parent link="blimp_stick"/>
    <child link="blimp_wing2"/>
  </joint>

  <joint name="base_rud_right" type="fixed">
    <origin rpy="-1.57075 0 -0.174533" xyz="-1.55 -0.85 0.05"/>
    <parent link="base"/>
    <child link="blimp_rud_right"/>
  </joint>

  <joint name="base_rud_left" type="fixed">
    <origin rpy="1.57075 0 0.174533" xyz="-1.55 0.85 0.05"/>
    <parent link="base"/>
    <child link="blimp_rud_left"/>
  </joint>

  <joint name="base_rud_top" type="fixed">
    <origin rpy="3.14159 -0.164533 0" xyz="-1.55 0 0.85"/>
    <parent link="base"/>
    <child link="blimp_rud_top"/>
  </joint>

  <joint name="base_rud_bot" type="fixed">
    <origin rpy="0 0.164533 0" xyz="-1.55 0 -0.85"/>
    <parent link="base"/>
    <child link="blimp_rud_bot"/>
  </joint>

  <joint name="rud_right" type="revolute">
    <!-- <origin rpy="-1.57075 0 -0.174533" xyz="-1.68 -0.7 0.05"/> -->
    <origin xyz="-0.28 0 0"/>
    <parent link="blimp_rud_right"/>
    <child link="rud_right"/>
    <axis xyz="0 0 1"/>
    <limit  lower="-0.523599" upper="0.523599" velocity="15.0"/>
  </joint>

  <joint name="rud_left" type="revolute">
    <origin xyz="-0.28 0 0"/>
    <parent link="blimp_rud_left"/>
    <child link="rud_left"/>
    <axis xyz="0 0 1"/>
    <limit  lower="-0.523599" upper="0.523599" velocity="15.0"/>
  </joint>

  <joint name="rud_top" type="revolute">
    <origin xyz="-0.28 0 0"/>
    <parent link="blimp_rud_top"/>
    <child link="rud_top"/>
    <axis xyz="0 0 1"/>
    <limit  lower="-0.523599" upper="0.523599" velocity="15.0"/>
  </joint>

  <joint name="rud_bot" type="revolute">
    <origin xyz="-0.28 0 0"/>
    <parent link="blimp_rud_bot"/>
    <child link="rud_bot"/>
    <axis xyz="0 0 1"/>
    <limit  lower="-0.523599" upper="0.523599" velocity="15.0"/>
  </joint>

  <joint name="gondola_stick" type="revolute">
    <origin rpy="1.57075 0 0" xyz="1.06 0 -1.12"/>
    <parent link="gondola"/>
    <child link="blimp_stick"/>
    <axis xyz="0 0 1"/>    
    <limit  lower="-2.5" upper="2.5" velocity="15.0"/> 
  </joint>
</robot>
